data/partial_test.csv
action,order_type,side,price,quantity,order_id
ADD,LIMIT,BUY,100,50,
ADD,LIMIT,BUY,100,30,
ADD,LIMIT,SELL,100,20,
ADD,LIMIT,SELL,100,40,
ADD,LIMIT,SELL,100,15,
ADD,MARKET,BUY,100,25,
ADD,LIMIT,BUY,95,100,
ADD,LIMIT,SELL,95,60,
